Workbook

Sheet LEGENDA
A1: 1. Técnica
A2: 1.1 tabela_origem
A3: 1.1.1 base operacional;
A4: 1.1.2 fórmulas;
A5: 1.1.3 classificações;
A6: 1.1.4 PROVC
A7: 1.1.5 PROCX
A8: 1.1.6 SE
A9: 1.1.7 SOMASE
A10: 1.1.8 SOMASES
A11: 2. Apresentação Executiva
A12: 2.1 regional x período
... A15: 2.4 faturamento_faixa_horaria (2)
B17: estrutura técnica
B19: operação/distribuição
B21: comportamento temporal
B23: financeiro/ticket/faturamento
B26: Apresentação executiva

Sheet dimensao_bairro
A1: bairro | B1: regional_origem
A2: Água Verde | B2: Portão
A3: Água Verde | B3: Portão
A4: Água Verde | B4: Portão
A5: Água Verde | B5: Portão
A6: Água Verde | B6: Portão
A7: Água Verde | B7: Portão
A8: Água Verde | B8: Portão
A9: Água Verde | B9: Portão
A10: Água Verde | B10: Portão
A11: Água Verde | B11: Portão
A12: Água Verde | B12: Portão
... A590: Xaxim | B590: Boqueirão

Sheet tabela_origem
A1: data | B1: periodo | C1: horario | D1: faixa_horaria | E1: bairro_origem | F1: regional_origem | G1: bairro_destino | H1: valor_corrida | I1: distância_km | J1: faixa_distancia | M1: regional_origem_PROCV | N1: regional_origem_PROCX | O1: regional_origem_indice_CORRESP | P1: coluna_SE_classificacao_valor_corrida | Q1: coluna_CONT.SE_classificacao | R1: coluna_CONT.SE_quantidade | S1: coluna_SOMASE_faturamento | T1: coluna_SOMASES | U1: conteudo_SOMASES
A2: 46083 | B2: manhã | C2: 0.31527778 | D2: =TEXT(C2,"hh")&"h" -> 07h | E2: Guaíra | F2: =VLOOKUP(E2,dimensao_bairro!A:B,2,FALSE) -> Portão | G2: Jardim das Américas | H2: 35.3 | I2: 6.3 | J2: =IF(I2<=2,"Curta",IF(I2<=4,"Média","Longa")) -> Longa | M2: =VLOOKUP(E2,dimensao_bairro!A:B,2,FALSE) -> Portão | N2: =PROCX(E2,dimensao_bairro!A:A,dimensao_bairro!B:B) -> #NAME? | O2: =INDEX(dimensao_bairro!B:B,MATCH(tabela_origem!E2,dimensao_bairro!A:A,0)) -> Portão | P2: =IF(H2<7,"BAIXO",IF(H2<=10,"MÉDIO","ALTO")) -> ALTO | Q2: BAIXO | R2: =COUNTIF(P:P,"BAIXO") -> 304 | S2: =SUMIF(P:P,"BAIXO",H:H) -> 1995.32 | T2: G | U2: valor_venda
A3: 46083 | B3: manhã | C3: 0.34236111 | D3: =TEXT(C3,"hh")&"h" -> 08h | E3: Cajuru | F3: =VLOOKUP(E3,dimensao_bairro!A:B,2,FALSE) -> Cajuru | G3: Juvevê | H3: 21.9 | I3: 8.6 | J3: =IF(I3<=2,"Curta",IF(I3<=4,"Média","Longa")) -> Longa | M3: =VLOOKUP(E3,dimensao_bairro!A:B,2,FALSE) -> Cajuru | N3: =PROCX(1,#REF!,#REF!) -> #NAME? | O3: =INDEX(dimensao_bairro!B:B,MATCH(tabela_origem!E3,dimensao_bairro!A:A,0)) -> Cajuru | P3: =IF(H3<7,"BAIXO",IF(H3<=10,"MÉDIO","ALTO")) -> ALTO | Q3: MÉDIO | R3: =COUNTIF(P:P,"MÉDIO") -> 195 | S3: =SUMIF(P:P,"MÉDIO",H:H) -> 1592.82 | T3: O | U3: classificacao
A4: 46083 | B4: manhã | C4: 0.37013889 | D4: =TEXT(C4,"hh")&"h" -> 08h | E4: Juvevê | F4: =VLOOKUP(E4,dimensao_bairro!A:B,2,FALSE) -> Matriz | G4: Santa Cândida | H4: 14.14 | I4: 5.7 | J4: =IF(I4<=2,"Curta",IF(I4<=4,"Média","Longa")) -> Longa | M4: =VLOOKUP(E4,dimensao_bairro!A:B,2,FALSE) -> Matriz | O4: =INDEX(dimensao_bairro!B:B,MATCH(tabela_origem!E4,dimensao_bairro!A:A,0)) -> Matriz | P4: =IF(H4<7,"BAIXO",IF(H4<=10,"MÉDIO","ALTO")) -> ALTO | Q4: ALTO | R4: =COUNTIF(P:P,"ALTO") -> 90 | S4: =SUMIF(P:P,"ALTO",H:H) -> 1336.96 | T4: B | U4: periodo
A5: 46083 | B5: manhã | C5: 0.37986111 | D5: =TEXT(C5,"hh")&"h" -> 09h | E5: Boa Vista | F5: =VLOOKUP(E5,dimensao_bairro!A:B,2,FALSE) -> Boa Vista | G5: Cabral | H5: 12.2 | I5: 4.4 | J5: =IF(I5<=2,"Curta",IF(I5<=4,"Média","Longa")) -> Longa | M5: =VLOOKUP(E5,dimensao_bairro!A:B,2,FALSE) -> Boa Vista | O5: =INDEX(dimensao_bairro!B:B,MATCH(tabela_origem!E5,dimensao_bairro!A:A,0)) -> Boa Vista | P5: =IF(H5<7,"BAIXO",IF(H5<=10,"MÉDIO","ALTO")) -> ALTO | T5: S | U5: coluna_SOMASES
A6: 46083 | B6: manhã | C6: 0.39513889 | D6: =TEXT(C6,"hh")&"h" -> 09h | E6: Ahú | F6: =VLOOKUP(E6,dimensao_bairro!A:B,2,FALSE) -> Matriz | G6: São Francisco | H6: 9.8 | I6: 3.6 | J6: =IF(I6<=2,"Curta",IF(I6<=4,"Média","Longa")) -> Média | M6: =VLOOKUP(E6,dimensao_bairro!A:B,2,FALSE) -> Matriz | O6: =INDEX(dimensao_bairro!B:B,MATCH(tabela_origem!E6,dimensao_bairro!A:A,0)) -> Matriz | P6: =IF(H6<7,"BAIXO",IF(H6<=10,"MÉDIO","ALTO")) -> MÉDIO
A7: 46083 | B7: manhã | C7: 0.33611111 | D7: =TEXT(C7,"hh")&"h" -> 08h | E7: Cajuru | F7: =VLOOKUP(E7,dimensao_bairro!A:B,2,FALSE) -> Cajuru | G7: Cajuru | H7: 7.1 | I7: 1.2 | J7: =IF(I7<=2,"Curta",IF(I7<=4,"Média","Longa")) -> Curta | M7: =VLOOKUP(E7,dimensao_bairro!A:B,2,FALSE) -> Cajuru | O7: =INDEX(dimensao_bairro!B:B,MATCH(tabela_origem!E7,dimensao_bairro!A:A,0)) -> Cajuru | P7: =IF(H7<7,"BAIXO",IF(H7<=10,"MÉDIO","ALTO")) -> MÉDIO | T7: condicao | U7: resultado
A8: 46083 | B8: manhã | C8: 0.40972222 | D8: =TEXT(C8,"hh")&"h" -> 09h | E8: Centro | F8: =VLOOKUP(E8,dimensao_bairro!A:B,2,FALSE) -> Matriz | G8: Centro | H8: 6.6 | I8: 1.3 | J8: =IF(I8<=2,"Curta",IF(I8<=4,"Média","Longa")) -> Curta | M8: =VLOOKUP(E8,dimensao_bairro!A:B,2,FALSE) -> Matriz | O8: =INDEX(dimensao_bairro!B:B,MATCH(tabela_origem!E8,dimensao_bairro!A:A,0)) -> Matriz | P8: =IF(H8<7,"BAIXO",IF(H8<=10,"MÉDIO","ALTO")) -> BAIXO | T8: ALTO+TARDE | U8: =SUMIFS(H:H,P:P,"ALTO",B:B,"TARDE") -> 695.69
A9: 46083 | B9: manhã | C9: 0.40347222 | D9: =TEXT(C9,"hh")&"h" -> 09h | E9: São Francisco | F9: =VLOOKUP(E9,dimensao_bairro!A:B,2,FALSE) -> Matriz | G9: Centro | H9: 6.6 | I9: 1.8 | J9: =IF(I9<=2,"Curta",IF(I9<=4,"Média","Longa")) -> Curta | M9: =VLOOKUP(E9,dimensao_bairro!A:B,2,FALSE) -> Matriz | O9: =INDEX(dimensao_bairro!B:B,MATCH(tabela_origem!E9,dimensao_bairro!A:A,0)) -> Matriz | P9: =IF(H9<7,"BAIXO",IF(H9<=10,"MÉDIO","ALTO")) -> BAIXO | T9: ALTO+MANHÃ | U9: =SUMIFS(H:H,P:P,"ALTO",B:B,"MANHÃ") -> 641.27
A10: 46083 | B10: manhã | C10: 0.39236111 | D10: =TEXT(C10,"hh")&"h" -> 09h | E10: Cabral | F10: =VLOOKUP(E10,dimensao_bairro!A:B,2,FALSE) -> Matriz | G10: Ahú | H10: 6.5 | I10: 1 | J10: =IF(I10<=2,"Curta",IF(I10<=4,"Média","Longa")) -> Curta | M10: =VLOOKUP(E10,dimensao_bairro!A:B,2,FALSE) -> Matriz | O10: =INDEX(dimensao_bairro!B:B,MATCH(tabela_origem!E10,dimensao_bairro!A:A,0)) -> Matriz | P10: =IF(H10<7,"BAIXO",IF(H10<=10,"MÉDIO","ALTO")) -> BAIXO | T10: MÉDIO+TARDE | U10: =SUMIFS(H:H,P:P,"MÉDIO",B:B,"TARDE") -> 1090.11
A11: 46084 | B11: manhã | C11: 0.3125 | D11: =TEXT(C11,"hh")&"h" -> 07h | E11: Fanny | F11: =VLOOKUP(E11,dimensao_bairro!A:B,2,FALSE) -> Portão | G11: Centro | H11: 30.7 | I11: 8.2 | J11: =IF(I11<=2,"Curta",IF(I11<=4,"Média","Longa")) -> Longa | M11: =VLOOKUP(E11,dimensao_bairro!A:B,2,FALSE) -> Portão | O11: =INDEX(dimensao_bairro!B:B,MATCH(tabela_origem!E11,dimensao_bairro!A:A,0)) -> Portão | P11: =IF(H11<7,"BAIXO",IF(H11<=10,"MÉDIO","ALTO")) -> ALTO
A12: 46084 | B12: manhã | C12: 0.37430556 | D12: =TEXT(C12,"hh")&"h" -> 08h | E12: Boqueirão | F12: =VLOOKUP(E12,dimensao_bairro!A:B,2,FALSE) -> Boqueirão | G12: Parolin | H12: 12.1 | I12: 4.8 | J12: =IF(I12<=2,"Curta",IF(I12<=4,"Média","Longa")) -> Longa | M12: =VLOOKUP(E12,dimensao_bairro!A:B,2,FALSE) -> Boqueirão | O12: =INDEX(dimensao_bairro!B:B,MATCH(tabela_origem!E12,dimensao_bairro!A:A,0)) -> Boqueirão | P12: =IF(H12<7,"BAIXO",IF(H12<=10,"MÉDIO","ALTO")) -> ALTO
A13: 46084 | B13: manhã | C13: 0.33333333 | D13: =TEXT(C13,"hh")&"h" -> 08h | E13: Centro | F13: =VLOOKUP(E13,dimensao_bairro!A:B,2,FALSE) -> Matriz | G13: Guabirotuba | H13: 11.2 | I13: 5.3 | J13: =IF(I13<=2,"Curta",IF(I13<=4,"Média","Longa")) -> Longa | M13: =VLOOKUP(E13,dimensao_bairro!A:B,2,FALSE) -> Matriz | O13: =INDEX(dimensao_bairro!B:B,MATCH(tabela_origem!E13,dimensao_bairro!A:A,0)) -> Matriz | P13: =IF(H13<7,"BAIXO",IF(H13<=10,"MÉDIO","ALTO")) -> ALTO
A14: 46084 | B14: manhã | C14: 0.37083333 | D14: =TEXT(C14,"hh")&"h" -> 08h | E14: Fanny | F14: =VLOOKUP(E14,dimensao_bairro!A:B,2,FALSE) -> Portão | G14: Hauer | H14: 7.4 | I14: 1.9 | J14: =IF(I14<=2,"Curta",IF(I14<=4,"Média","Longa")) -> Curta | M14: =VLOOKUP(E14,dimensao_bairro!A:B,2,FALSE) -> Portão | O14: =INDEX(dimensao_bairro!B:B,MATCH(tabela_origem!E14,dimensao_bairro!A:A,0)) -> Portão | P14: =IF(H14<7,"BAIXO",IF(H14<=10,"MÉDIO","ALTO")) -> MÉDIO
A15: 46084 | B15: manhã | C15: 0.34791667 | D15: =TEXT(C15,"hh")&"h" -> 08h | E15: Guabirotuba | F15: =VLOOKUP(E15,dimensao_bairro!A:B,2,FALSE) -> Cajuru | G15: Hauer | H15: 6.9 | I15: 2.1 | J15: =IF(I15<=2,"Curta",IF(I15<=4,"Média","Longa")) -> Média | M15: =VLOOKUP(E15,dimensao_bairro!A:B,2,FALSE) -> Cajuru | O15: =INDEX(dimensao_bairro!B:B,MATCH(tabela_origem!E15,dimensao_bairro!A:A,0)) -> Cajuru | P15: =IF(H15<7,"BAIXO",IF(H15<=10,"MÉDIO","ALTO")) -> BAIXO
A16: 46084 | B16: manhã | C16: 0.41041667 | D16: =TEXT(C16,"hh")&"h" -> 09h | E16: Água Verde | F16: =VLOOKUP(E16,dimensao_bairro!A:B,2,FALSE) -> Portão | G16: Rebouças | H16: 6.6 | I16: 1.7 | J16: =IF(I16<=2,"Curta",IF(I16<=4,"Média","Longa")) -> Curta | M16: =VLOOKUP(E16,dimensao_bairro!A:B,2,FALSE) -> Portão | O16: =INDEX(dimensao_bairro!B:B,MATCH(tabela_origem!E16,dimensao_bairro!A:A,0)) -> Portão | P16: =IF(H16<7,"BAIXO",IF(H16<=10,"MÉDIO","ALTO")) -> BAIXO
A17: 46084 | B17: manhã | C17: 0.3875 | D17: =TEXT(C17,"hh")&"h" -> 09h | E17: Parolin | F17: =VLOOKUP(E17,dimensao_bairro!A:B,2,FALSE) -> Portão | G17: Parolin | H17: 6.5 | I17: 0.5 | J17: =IF(I17<=2,"Curta",IF(I17<=4,"Média","Longa")) -> Curta | M17: =VLOOKUP(E17,dimensao_bairro!A:B,2,FALSE) -> Portão | O17: =INDEX(dimensao_bairro!B:B,MATCH(tabela_origem!E17,dimensao_bairro!A:A,0)) -> Portão | P17: =IF(H17<7,"BAIXO",IF(H17<=10,"MÉDIO","ALTO")) -> BAIXO
A18: 46084 | B18: manhã | C18: 0.39305556 | D18: =TEXT(C18,"hh")&"h" -> 09h | E18: Parolin | F18: =VLOOKUP(E18,dimensao_bairro!A:B,2,FALSE) -> Portão | G18: Água Verde | H18: 6.5 | I18: 3.1 | J18: =IF(I18<=2,"Curta",IF(I18<=4,"Média","Longa")) -> Média | M18: =VLOOKUP(E18,dimensao_bairro!A:B,2,FALSE) -> Portão | O18: =INDEX(dimensao_bairro!B:B,MATCH(tabela_origem!E18,dimensao_bairro!A:A,0)) -> Portão | P18: =IF(H18<7,"BAIXO",IF(H18<=10,"MÉDIO","ALTO")) -> BAIXO
A19: 46085 | B19: manhã | C19: 0.32569444 | D19: =TEXT(C19,"hh")&"h" -> 07h | E19: Vila Izabel | F19: =VLOOKUP(E19,dimensao_bairro!A:B,2,FALSE) -> Portão | G19: Seminário | H19: 12.4 | I19: 2.2 | J19: =IF(I19<=2,"Curta",IF(I19<=4,"Média","Longa")) -> Média | M19: =VLOOKUP(E19,dimensao_bairro!A:B,2,FALSE) -> Portão | O19: =INDEX(dimensao_bairro!B:B,MATCH(tabela_origem!E19,dimensao_bairro!A:A,0)) -> Portão | P19: =IF(H19<7,"BAIXO",IF(H19<=10,"MÉDIO","ALTO")) -> ALTO
A20: 46085 | B20: manhã | C20: 0.31458333 | D20: =TEXT(C20,"hh")&"h" -> 07h | E20: Vila Izabel | F20: =VLOOKUP(E20,dimensao_bairro!A:B,2,FALSE) -> Portão | G20: Mercês | H20: 7.9 | I20: 1.3 | J20: =IF(I20<=2,"Curta",IF(I20<=4,"Média","Longa")) -> Curta | M20: =VLOOKUP(E20,dimensao_bairro!A:B,2,FALSE) -> Portão | O20: =INDEX(dimensao_bairro!B:B,MATCH(tabela_origem!E20,dimensao_bairro!A:A,0)) -> Portão | P20: =IF(H20<7,"BAIXO",IF(H20<=10,"MÉDIO","ALTO")) -> MÉDIO
A21: 46085 | B21: manhã | C21: 0.36875 | D21: =TEXT(C21,"hh")&"h" -> 08h | E21: Centro | F21: =VLOOKUP(E21,dimensao_bairro!A:B,2,FALSE) -> Matriz | G21: Seminário | H21: 7.4 | I21: 2 | J21: =IF(I21<=2,"Curta",IF(I21<=4,"Média","Longa")) -> Curta | M21: =VLOOKUP(E21,dimensao_bairro!A:B,2,FALSE) -> Matriz | O21: =INDEX(dimensao_bairro!B:B,MATCH(tabela_origem!E21,dimensao_bairro!A:A,0)) -> Matriz | P21: =IF(H21<7,"BAIXO",IF(H21<=10,"MÉDIO","ALTO")) -> MÉDIO
A22: 46085 | B22: manhã | C22: 0.34930556 | D22: =TEXT(C22,"hh")&"h" -> 08h | E22: Santa Quitéria | F22: =VLOOKUP(E22,dimensao_bairro!A:B,2,FALSE) -> Portão | G22: Seminário | H22: 6.9 | I22: 1.9 | J22: =IF(I22<=2,"Curta",IF(I22<=4,"Média","Longa")) -> Curta | M22: =VLOOKUP(E22,dimensao_bairro!A:B,2,FALSE) -> Portão | O22: =INDEX(dimensao_bairro!B:B,MATCH(tabela_origem!E22,dimensao_bairro!A:A,0)) -> Portão | P22: =IF(H22<7,"BAIXO",IF(H22<=10,"MÉDIO","ALTO")) -> BAIXO
... A415: 46097 | B415: tarde | C415: 0.65486111 | D415: =TEXT(C415,"hh")&"h" -> 15h | E415: Hauer | F415: =VLOOKUP(E415,dimensao_bairro!A:B,2,FALSE) -> Boqueirão | G415: Parolin | H415: 6.5 | I415: 1.6 | J415: =IF(I415<=2,"Curta",IF(I415<=4,"Média","Longa")) -> Curta | M415: =VLOOKUP(E415,dimensao_bairro!A:B,2,FALSE) -> Boqueirão | O415: =INDEX(dimensao_bairro!B:B,MATCH(tabela_origem!E415,dimensao_bairro!A:A,0)) -> Boqueirão | P415: =IF(H415<7,"BAIXO",IF(H415<=10,"MÉDIO","ALTO")) -> BAIXO
A416: 46097 | B416: tarde | C416: 0.66180556 | D416: =TEXT(C416,"hh")&"h" -> 15h | E416: Hauer | F416: =VLOOKUP(E416,dimensao_bairro!A:B,2,FALSE) -> Boqueirão | H416: 6.5 | I416: 1.9 | J416: =IF(I416<=2,"Curta",IF(I416<=4,"Média","Longa")) -> Curta | M416: =VLOOKUP(E416,dimensao_bairro!A:B,2,FALSE) -> Boqueirão | O416: =INDEX(dimensao_bairro!B:B,MATCH(tabela_origem!E416,dimensao_bairro!A:A,0)) -> Boqueirão | P416: =IF(H416<7,"BAIXO",IF(H416<=10,"MÉDIO","ALTO")) -> BAIXO
A417: 46098 | B417: tarde | D417: =TEXT(C417,"hh")&"h" -> 00h | F417: =VLOOKUP(E417,dimensao_bairro!A:B,2,FALSE) -> #N/A | G417: Guaíra | J417: =IF(I417<=2,"Curta",IF(I417<=4,"Média","Longa")) -> Curta | M417: =VLOOKUP(E417,dimensao_bairro!A:B,2,FALSE) -> #N/A | O417: =INDEX(dimensao_bairro!B:B,MATCH(tabela_origem!E417,dimensao_bairro!A:A,0)) -> #N/A | P417: =IF(H417<7,"BAIXO",IF(H417<=10,"MÉDIO","ALTO")) -> BAIXO
A418: 46099 | B418: tarde | C418: 0.72916667 | D418: =TEXT(C418,"hh")&"h" -> 17h | E418: Guabirotuba | F418: =VLOOKUP(E418,dimensao_bairro!A:B,2,FALSE) -> Cajuru | G418: Xaxim | H418: 17.2 | I418: 5.6 | J418: =IF(I418<=2,"Curta",IF(I418<=4,"Média","Longa")) -> Longa | M418: =VLOOKUP(E418,dimensao_bairro!A:B,2,FALSE) -> Cajuru | O418: =INDEX(dimensao_bairro!B:B,MATCH(tabela_origem!E418,dimensao_bairro!A:A,0)) -> Cajuru | P418: =IF(H418<7,"BAIXO",IF(H418<=10,"MÉDIO","ALTO")) -> ALTO
A419: 46099 | B419: tarde | C419: 0.75138889 | D419: =TEXT(C419,"hh")&"h" -> 18h | E419: Hauer | F419: =VLOOKUP(E419,dimensao_bairro!A:B,2,FALSE) -> Boqueirão | G419: Boqueirão | H419: 17 | I419: 4.9 | J419: =IF(I419<=2,"Curta",IF(I419<=4,"Média","Longa")) -> Longa | M419: =VLOOKUP(E419,dimensao_bairro!A:B,2,FALSE) -> Boqueirão | O419: =INDEX(dimensao_bairro!B:B,MATCH(tabela_origem!E419,dimensao_bairro!A:A,0)) -> Boqueirão | P419: =IF(H419<7,"BAIXO",IF(H419<=10,"MÉDIO","ALTO")) -> ALTO
A420: 46099 | B420: tarde | C420: 0.80277778 | D420: =TEXT(C420,"hh")&"h" -> 19h | E420: Xaxim | F420: =VLOOKUP(E420,dimensao_bairro!A:B,2,FALSE) -> Boqueirão | G420: Xaxim | H420: 11.6 | I420: 5 | J420: =IF(I420<=2,"Curta",IF(I420<=4,"Média","Longa")) -> Longa | M420: =VLOOKUP(E420,dimensao_bairro!A:B,2,FALSE) -> Boqueirão | O420: =INDEX(dimensao_bairro!B:B,MATCH(tabela_origem!E420,dimensao_bairro!A:A,0)) -> Boqueirão | P420: =IF(H420<7,"BAIXO",IF(H420<=10,"MÉDIO","ALTO")) -> ALTO
A421: 46099 | B421: tarde | C421: 0.79652778 | D421: =TEXT(C421,"hh")&"h" -> 19h | E421: Boqueirão | F421: =VLOOKUP(E421,dimensao_bairro!A:B,2,FALSE) -> Boqueirão | G421: Uberaba | H421: 10.3 | I421: 3.9 | J421: =IF(I421<=2,"Curta",IF(I421<=4,"Média","Longa")) -> Média | M421: =VLOOKUP(E421,dimensao_bairro!A:B,2,FALSE) -> Boqueirão | O421: =INDEX(dimensao_bairro!B:B,MATCH(tabela_origem!E421,dimensao_bairro!A:A,0)) -> Boqueirão | P421: =IF(H421<7,"BAIXO",IF(H421<=10,"MÉDIO","ALTO")) -> ALTO
A422: 46099 | B422: tarde | C422: 0.71458333 | D422: =TEXT(C422,"hh")&"h" -> 17h | E422: Hauer | F422: =VLOOKUP(E422,dimensao_bairro!A:B,2,FALSE) -> Boqueirão | G422: Hauer | H422: 10 | I422: 2.9 | J422: =IF(I422<=2,"Curta",IF(I422<=4,"Média","Longa")) -> Média | M422: =VLOOKUP(E422,dimensao_bairro!A:B,2,FALSE) -> Boqueirão | O422: =INDEX(dimensao_bairro!B:B,MATCH(tabela_origem!E422,dimensao_bairro!A:A,0)) -> Boqueirão | P422: =IF(H422<7,"BAIXO",IF(H422<=10,"MÉDIO","ALTO")) -> MÉDIO
A423: 46099 | B423: tarde | C423: 0.70138889 | D423: =TEXT(C423,"hh")&"h" -> 16h | E423: Hauer | F423: =VLOOKUP(E423,dimensao_bairro!A:B,2,FALSE) -> Boqueirão | G423: Xaxim | H423: 8.8 | I423: 1.3 | J423: =IF(I423<=2,"Curta",IF(I423<=4,"Média","Longa")) -> Curta | M423: =VLOOKUP(E423,dimensao_bairro!A:B,2,FALSE) -> Boqueirão | O423: =INDEX(dimensao_bairro!B:B,MATCH(tabela_origem!E423,dimensao_bairro!A:A,0)) -> Boqueirão | P423: =IF(H423<7,"BAIXO",IF(H423<=10,"MÉDIO","ALTO")) -> MÉDIO
A424: 46099 | B424: tarde | C424: 0.82430556 | D424: =TEXT(C424,"hh")&"h" -> 19h | E424: Boqueirão | F424: =VLOOKUP(E424,dimensao_bairro!A:B,2,FALSE) -> Boqueirão | G424: Lindóia | H424: 8.5 | I424: 3.8 | J424: =IF(I424<=2,"Curta",IF(I424<=4,"Média","Longa")) -> Média | M424: =VLOOKUP(E424,dimensao_bairro!A:B,2,FALSE) -> Boqueirão | O424: =INDEX(dimensao_bairro!B:B,MATCH(tabela_origem!E424,dimensao_bairro!A:A,0)) -> Boqueirão | P424: =IF(H424<7,"BAIXO",IF(H424<=10,"MÉDIO","ALTO")) -> MÉDIO
A425: 46099 | B425: tarde | C425: 0.74513889 | D425: =TEXT(C425,"hh")&"h" -> 17h | E425: Parolin | F425: =VLOOKUP(E425,dimensao_bairro!A:B,2,FALSE) -> Portão | G425: Hauer | H425: 8.3 | I425: 1.9 | J425: =IF(I425<=2,"Curta",IF(I425<=4,"Média","Longa")) -> Curta | M425: =VLOOKUP(E425,dimensao_bairro!A:B,2,FALSE) -> Portão | O425: =INDEX(dimensao_bairro!B:B,MATCH(tabela_origem!E425,dimensao_bairro!A:A,0)) -> Portão | P425: =IF(H425<7,"BAIXO",IF(H425<=10,"MÉDIO","ALTO")) -> MÉDIO
A426: 46099 | B426: tarde | C426: 0.77777778 | D426: =TEXT(C426,"hh")&"h" -> 18h | E426: Boqueirão | F426: =VLOOKUP(E426,dimensao_bairro!A:B,2,FALSE) -> Boqueirão | G426: Xaxim | H426: 8 | I426: 2 | J426: =IF(I426<=2,"Curta",IF(I426<=4,"Média","Longa")) -> Curta | M426: =VLOOKUP(E426,dimensao_bairro!A:B,2,FALSE) -> Boqueirão | O426: =INDEX(dimensao_bairro!B:B,MATCH(tabela_origem!E426,dimensao_bairro!A:A,0)) -> Boqueirão | P426: =IF(H426<7,"BAIXO",IF(H426<=10,"MÉDIO","ALTO")) -> MÉDIO
A427: 46099 | B427: tarde | C427: 0.76875 | D427: =TEXT(C427,"hh")&"h" -> 18h | E427: Xaxim | F427: =VLOOKUP(E427,dimensao_bairro!A:B,2,FALSE) -> Boqueirão | G427: Hauer | H427: 6.9 | I427: 0.7 | J427: =IF(I427<=2,"Curta",IF(I427<=4,"Média","Longa")) -> Curta | M427: =VLOOKUP(E427,dimensao_bairro!A:B,2,FALSE) -> Boqueirão | O427: =INDEX(dimensao_bairro!B:B,MATCH(tabela_origem!E427,dimensao_bairro!A:A,0)) -> Boqueirão | P427: =IF(H427<7,"BAIXO",IF(H427<=10,"MÉDIO","ALTO")) -> BAIXO
A428: 46099 | B428: tarde | C428: 0.68888889 | D428: =TEXT(C428,"hh")&"h" -> 16h | E428: Boqueirão | F428: =VLOOKUP(E428,dimensao_bairro!A:B,2,FALSE) -> Boqueirão | G428: Hauer | H428: 6.5 | I428: 2.2 | J428: =IF(I428<=2,"Curta",IF(I428<=4,"Média","Longa")) -> Média | M428: =VLOOKUP(E428,dimensao_bairro!A:B,2,FALSE) -> Boqueirão | O428: =INDEX(dimensao_bairro!B:B,MATCH(tabela_origem!E428,dimensao_bairro!A:A,0)) -> Boqueirão | P428: =IF(H428<7,"BAIXO",IF(H428<=10,"MÉDIO","ALTO")) -> BAIXO
A429: 46099 | B429: tarde | C429: 0.71180556 | D429: =TEXT(C429,"hh")&"h" -> 17h | E429: Boqueirão | F429: =VLOOKUP(E429,dimensao_bairro!A:B,2,FALSE) -> Boqueirão | G429: Hauer | H429: 6.5 | I429: 2.2 | J429: =IF(I429<=2,"Curta",IF(I429<=4,"Média","Longa")) -> Média | M429: =VLOOKUP(E429,dimensao_bairro!A:B,2,FALSE) -> Boqueirão | O429: =INDEX(dimensao_bairro!B:B,MATCH(tabela_origem!E429,dimensao_bairro!A:A,0)) -> Boqueirão | P429: =IF(H429<7,"BAIXO",IF(H429<=10,"MÉDIO","ALTO")) -> BAIXO
... A589: 46108 | B589: tarde | C589: 0.66666667 | D589: =TEXT(C589,"hh")&"h" -> 16h | E589: Água Verde | F589: =VLOOKUP(E589,dimensao_bairro!A:B,2,FALSE) -> Portão | G589: Rebouças | H589: 6.5 | I589: 1.4 | J589: =IF(I589<=2,"Curta",IF(I589<=4,"Média","Longa")) -> Curta | M589: =VLOOKUP(E589,dimensao_bairro!A:B,2,FALSE) -> Portão | O589: =INDEX(dimensao_bairro!B:B,MATCH(tabela_origem!E589,dimensao_bairro!A:A,0)) -> Portão | P589: =IF(H589<7,"BAIXO",IF(H589<=10,"MÉDIO","ALTO")) -> BAIXO
A590: 46108 | B590: tarde | C590: 0.62847222 | D590: =TEXT(C590,"hh")&"h" -> 15h | E590: Água Verde | F590: =VLOOKUP(E590,dimensao_bairro!A:B,2,FALSE) -> Portão | H590: 6.5 | I590: 1.5 | J590: =IF(I590<=2,"Curta",IF(I590<=4,"Média","Longa")) -> Curta | M590: =VLOOKUP(E590,dimensao_bairro!A:B,2,FALSE) -> Portão | O590: =INDEX(dimensao_bairro!B:B,MATCH(tabela_origem!E590,dimensao_bairro!A:A,0)) -> Portão | P590: =IF(H590<7,"BAIXO",IF(H590<=10,"MÉDIO","ALTO")) -> BAIXO
E591: Portão | F591: =VLOOKUP(E591,dimensao_bairro!A:B,2,FALSE) -> Portão
...

Sheet Análise_faixa_distancia
A1: Faixa_distancia | B1: Qtd. Corridas | C1: faturamento | D1: ticket_medio
A2: Curta | B2: 252 | C2: 1777.79 | D2: 7.0547222
A3: Longa | B3: 65 | C3: 1003.91 | D3: 15.444769
A4: Média | B4: 271 | C4: 2143.4 | D4: 7.9092251
A5: Total Geral | B5: 588 | C5: 4925.1 | D5: 8.3760204

Sheet faixa_distancia x periodo
A1: Contagem de distância_km | B1: Rótulos de Coluna
A2: Rótulos de Linha | B2: Curta | C2: Longa | D2: Média | E2: Total Geral
A3: manhã | B3: 79 | C3: 30 | D3: 95 | E3: 204
A4: tarde | B4: 173 | C4: 35 | D4: 176 | E4: 384
A5: Total Geral | B5: 252 | C5: 65 | D5: 271 | E5: 588

Sheet comportamento_op_pulverizado
A1: horário | B1: Qtd. Corridas
A2: 0.30694444 | B2: 1
A3: 0.31041667 | B3: 2
A4: 0.31180556 | B4: 1
A5: 0.3125 | B5: 1
A6: 0.31319444 | B6: 1
A7: 0.31388889 | B7: 1
A8: 0.31458333 | B8: 1
A9: 0.31527778 | B9: 3
A10: 0.31597222 | B10: 1
A11: 0.31666667 | B11: 3
A12: 0.31805556 | B12: 3
A13: 0.31875 | B13: 1
... A351: 0.84513889 | B351: 1
A352: (vazio)
A353: Total Geral | B353: 588

Sheet comportamento_agrupamento_horas
A1: Rótulos de Linha | B1: Contagem de valor_corrida
A2: 00h
A3: 07h | B3: 47
A4: 08h | B4: 80
A5: 09h | B5: 72
A6: 10h | B6: 5
A7: 15h | B7: 63
A8: 16h | B8: 88
A9: 17h | B9: 83
A10: 18h | B10: 78
A11: 19h | B11: 68
A12: 20h | B12: 4
A13: Total Geral | B13: 588

Sheet ticket_medio_faixa_horaria
A1: Rótulos de Linha | B1: Média de valor_corrida
A2: 00h
A3: 07h | B3: 13.559149
A4: 08h | B4: 7.867375
A5: 09h | B5: 7.3434722
A6: 10h | B6: 6.96
A7: 15h | B7: 6.8934921
A8: 16h | B8: 7.6057955
A9: 17h | B9: 9.6026506
A10: 18h | B10: 8.3202564
A11: 19h | B11: 7.6308824
A12: 20h | B12: 6.6
A13: Total Geral | B13: 8.3760204

Sheet ticket_medio x distancia x peri
A3: Média de valor_corrida | B3: Rótulos de Coluna
A4: Rótulos de Linha | B4: Curta | C4: Média | D4: Longa | E4: Total Geral
A5: manhã | B5: 7.2258228 | C5: 7.9483158 | D5: 16.809 | E5: 8.9715686
A6: tarde | B6: 6.9765896 | C6: 7.888125 | D6: 14.275429 | E6: 8.0596354
A7: Total Geral | B7: 7.0547222 | C7: 7.9092251 | D7: 15.444769 | E7: 8.3760204

Sheet faturamento_faixa_horaria
A1: faixa_horaria | B1: faturamento
A2: 00h
A3: 07h | B3: 637.28
A4: 08h | B4: 629.39
A5: 09h | B5: 528.73
A6: 10h | B6: 34.8
A7: 15h | B7: 434.29
A8: 16h | B8: 669.31
A9: 17h | B9: 797.02
A10: 18h | B10: 648.98
A11: 19h | B11: 518.9
A12: 20h | B12: 26.4
A13: (vazio)
A14: Total Geral | B14: 4925.1

Sheet regional x periodo
A1: Soma de valor_corrida | B1: Rótulos de Coluna
A2: Rótulos de Linha | B2: tarde | C2: manhã | D2: Total Geral
A3: Portão | B3: 1440.4 | C3: 1124.62 | D3: 2565.02
A4: Boqueirão | B4: 893.81 | C4: 225 | D4: 1118.81
A5: Matriz | B5: 350.26 | C5: 258.59 | D5: 608.85
A6: Pinheirinho | B6: 101.7 | C6: 119.49 | D6: 221.19
A7: Bairro Novo | B7: 167.24 | C7: 6.6 | D7: 173.84
A8: Cajuru | B8: 98.4 | C8: 70.7 | D8: 169.1
A9: CIC | B9: 20.89 | C9: 6.5 | D9: 27.39
A10: Santa Felicidade | B10: 15.7 | C10: 6.5 | D10: 22.2
A11: Boa Vista | B11: 6.5 | C11: 12.2 | D11: 18.7
A12: Total Geral | B12: 3094.9 | C12: 1830.2 | D12: 4925.1

Sheet ticket_medio_faixa_horaria (2)
A1: Rótulos de Linha | B1: Média de valor_corrida
A2: 07h | B2: 13.559149
A3: 17h | B3: 9.6026506
A4: 18h | B4: 8.3202564
A5: 08h | B5: 7.867375
A6: 19h | B6: 7.6308824
A7: 16h | B7: 7.6057955
A8: 09h | B8: 7.3434722
A9: 10h | B9: 6.96
A10: 15h | B10: 6.8934921
A11: 20h | B11: 6.6
A12: Total Geral | B12: 8.3760204

Sheet comportamento_agrupamento_h (2
A1: faixa por hora | B1: Contagem de valor_corrida
A2: 16h | B2: 88
A3: 17h | B3: 83
A4: 08h | B4: 80
A5: 18h | B5: 78
A6: 09h | B6: 72
A7: 19h | B7: 68
A8: 15h | B8: 63
A9: 07h | B9: 47
A10: 10h | B10: 5
A11: 20h | B11: 4
A12: 00h
A13: Total Geral | B13: 588

Sheet faturamento_faixa_horaria (2)
A1: faixa_horaria | B1: faturamento
A2: 07h | B2: 637.28
A3: 08h | B3: 629.39
A4: 09h | B4: 528.73
A5: 10h | B5: 34.8
A6: 15h | B6: 434.29
A7: 16h | B7: 669.31
A8: 17h | B8: 797.02
A9: 18h | B9: 648.98
A10: 19h | B10: 518.9
A11: 20h | B11: 26.4
A12: Total Geral | B12: 4925.1

Sheet regional x faixa_distancia
A1: Contagem de valor_corrida | B1: Valor Corrida
A2: Rótulos de Linha | B2: Curta | C2: Longa | D2: Média | E2: Total Geral
A3: Portão | B3: 136 | C3: 26 | D3: 148 | E3: 310
A4: Boqueirão | B4: 57 | C4: 22 | D4: 56 | E4: 135
A5: Matriz | B5: 35 | C5: 7 | D5: 33 | E5: 75
A6: Bairro Novo | B6: 13 | C6: 1 | D6: 11 | E6: 25
A7: Cajuru | B7: 5 | C7: 4 | D7: 6 | E7: 15
A8: Pinheirinho | B8: 4 | C8: 3 | D8: 13 | E8: 20
A9: Boa Vista | B9: 1 | C9: 1 | E9: 2
A10: Santa Felicidade | B10: 1 | C10: 1 | E10: 2
A11: CIC | D11: 4 | E11: 4
A12: Total Geral | B12: 252 | C12: 65 | D12: 271 | E12: 588

Sheet ticket_medio_regional
A3: Rótulos de Linha | B3: Média de valor_corrida
A4: Cajuru | B4: 11.273333
A5: Santa Felicidade | B5: 11.1
A6: Pinheirinho | B6: 11.0595
A7: Boa Vista | B7: 9.35
A8: Boqueirão | B8: 8.2874815
A9: Portão | B9: 8.2742581
A10: Matriz | B10: 8.118
A11: Bairro Novo | B11: 6.9536
A12: CIC | B12: 6.8475
A13: #N/D
A14: Total Geral | B14: 8.3760204

Sheet produtividade_regional
A1: Rótulos de Linha | B1: Contagem de valor_corrida
A2: Portão | B2: 310
A3: Boqueirão | B3: 135
A4: Matriz | B4: 75
A5: Bairro Novo | B5: 25
A6: Pinheirinho | B6: 20
A7: Cajuru | B7: 15
A8: CIC | B8: 4
A9: Santa Felicidade | B9: 2
A10: Boa Vista | B10: 2
A11: Total Geral | B11: 588

Sheet produtividade x ticket
A1: Regional | B1: Qtd. Corridas | C1: Ticket médio
A2: Portão | B2: 310 | C2: 8.2742581
A3: Boqueirão | B3: 135 | C3: 8.2874815
A4: Matriz | B4: 75 | C4: 8.118
A5: Bairro Novo | B5: 25 | C5: 6.9536
A6: Pinheirinho | B6: 20 | C6: 11.0595
A7: Cajuru | B7: 15 | C7: 11.273333
A8: CIC | B8: 4 | C8: 6.8475
A9: Santa Felicidade | B9: 2 | C9: 11.1
A10: Boa Vista | B10: 2 | C10: 9.35
A11: Total Geral | B11: 588 | C11: 8.3760204

Sheet rentabilidade_regional
A1: Regional | B1: Faturamento | C1: Qtd. Corridas | D1: Ticket médio
A2: Portão | B2: 2565.02 | C2: 310 | D2: 8.2742581
A3: Boqueirão | B3: 1118.81 | C3: 135 | D3: 8.2874815
A4: Matriz | B4: 608.85 | C4: 75 | D4: 8.118
A5: Pinheirinho | B5: 221.19 | C5: 20 | D5: 11.0595
A6: Bairro Novo | B6: 173.84 | C6: 25 | D6: 6.9536
A7: Cajuru | B7: 169.1 | C7: 15 | D7: 11.273333
A8: CIC | B8: 27.39 | C8: 4 | D8: 6.8475
A9: Santa Felicidade | B9: 22.2 | C9: 2 | D9: 11.1
A10: Boa Vista | B10: 18.7 | C10: 2 | D10: 9.35
A11: Total Geral | B11: 4925.1 | C11: 588 | D11: 8.3760204

Sheet dashboard_operacional
A1: Soma | B1: Contagem | C1: Ticket médio | D1: distância_média_km
A2: 4925.1 | B2: 588 | C2: 8.3760204 | D2: 2.5295918
